09-03-2016 , Version 2.10b HomologaciónInstallDir C:\PROGRA~1\PyAfipWs1.16d HomologaciónC:\PROGRA~1\PyAfipWsappserver status OKdbserver status OKauthserver status OKWSFE.CompUltimoAutorizado(1,27)600: ValidacionDeToken: No apareció CUIT en lista de relaciones: 20078131455
09-03-2016 , Version 2.10b HomologaciónInstallDir C:\PROGRA~1\PyAfipWs1.16d HomologaciónC:\PROGRA~1\PyAfipWsappserver status OKdbserver status OKauthserver status OKWSFE.CompUltimoAutorizado(1,27)602: No existen datos en nuestros registros para los parametros ingresados.
09-03-2016 , Version 2.10b HomologaciónInstallDir C:\PROGRA~1\PyAfipWs1.16d HomologaciónC:\PROGRA~1\PyAfipWsappserver status OKdbserver status OKauthserver status OKWSFE.CompUltimoAutorizado(1,27)602: No existen datos en nuestros registros para los parametros ingresados.
09-03-2016 , Version 2.10b HomologaciónInstallDir C:\PROGRA~1\PyAfipWs1.16d HomologaciónC:\PROGRA~1\PyAfipWsappserver status OKdbserver status OKauthserver status OKWSFE.CompUltimoAutorizado(1,27)Orden:110051: Los importes informados en AlicIVA no se corresponden con los porcentajes.602: No existen datos en nuestros registros para los parametros ingresados.
09-03-2016 , Version 2.10b HomologaciónInstallDir C:\PROGRA~1\PyAfipWs1.16d HomologaciónC:\PROGRA~1\PyAfipWsappserver status OKdbserver status OKauthserver status OKWSFE.CompUltimoAutorizado(1,27)Orden:110051: Los importes informados en AlicIVA no se corresponden con los porcentajes.602: No existen datos en nuestros registros para los parametros ingresados.
09-03-2016 , Version 2.10b HomologaciónInstallDir C:\PROGRA~1\PyAfipWs1.16d HomologaciónC:\PROGRA~1\PyAfipWsappserver status OKdbserver status OKauthserver status OKWSFE.CompUltimoAutorizado(1,27)Orden:110070: Si ImpNeto es mayor a 0 el objeto IVA es obligatorio.602: No existen datos en nuestros registros para los parametros ingresados.
18-03-2016 , Version 2.10b HomologaciónInstallDir C:\PROGRA~1\PyAfipWs1.16d HomologaciónC:\PROGRA~1\PyAfipWsCodigo error afip:*****Numero de Error: 1429Mensaje de Error: Código de excepción OLE IDispatch 0 de Python COM Server Internal Error: Unexpected Python Error: Traceback (most recent call last):
  File "win32com\server\policy.pyc", line 277, in _Invoke_
  File "win32com\server\policy.pyc", line 282, in _invoke_
  File "win32com\server\policy.pyc", line 585, in _invokeex_
  File "utils.pyc", line 152, in capturar_errores_wrapper
  File "utils.pyc", line 375, in SetTicketAcceso
RuntimeError: Ticket de Acceso vacio!
Linea de codigo de error: wsfe.SetTicketAcceso(ta)Procedimiento: sw_conectarError VFP: Código de excepción OLE IDispatch 0 de Python COM Server Internal Error: Unexpected Python Error: Traceback (most recent call last):
  File "win32com\server\policy.pyc", line 277, in _Invoke_
  File "win32com\server\policy.pyc", line 282, in _invoke_
  File "win32com\server\policy.pyc", line 585, in _invokeex_
  File "utils.pyc", line 152, in capturar_errores_wrapper
  File "utils.pyc", line 375, in SetTicketAcceso
RuntimeError: Ticket de Acceso vacio!
.Exepción: RuntimeError: Ticket de Acceso vacio!
Traceback: Traceback (most recent call last):
  File "utils.pyc", line 152, in capturar_errores_wrapper
  File "utils.pyc", line 375, in SetTicketAcceso
RuntimeError: Ticket de Acceso vacio!

18-03-2016 , Version 2.10b HomologaciónInstallDir C:\PROGRA~1\PyAfipWs1.16d HomologaciónC:\PROGRA~1\PyAfipWsCodigo error afip:*****Numero de Error: 1429Mensaje de Error: Código de excepción OLE IDispatch 0 de Python COM Server Internal Error: Unexpected Python Error: Traceback (most recent call last):
  File "win32com\server\policy.pyc", line 277, in _Invoke_
  File "win32com\server\policy.pyc", line 282, in _invoke_
  File "win32com\server\policy.pyc", line 585, in _invokeex_
  File "utils.pyc", line 152, in capturar_errores_wrapper
  File "utils.pyc", line 375, in SetTicketAcceso
RuntimeError: Ticket de Acceso vacio!
Linea de codigo de error: wsfe.SetTicketAcceso(ta)Procedimiento: sw_conectarError VFP: Código de excepción OLE IDispatch 0 de Python COM Server Internal Error: Unexpected Python Error: Traceback (most recent call last):
  File "win32com\server\policy.pyc", line 277, in _Invoke_
  File "win32com\server\policy.pyc", line 282, in _invoke_
  File "win32com\server\policy.pyc", line 585, in _invokeex_
  File "utils.pyc", line 152, in capturar_errores_wrapper
  File "utils.pyc", line 375, in SetTicketAcceso
RuntimeError: Ticket de Acceso vacio!
.Exepción: RuntimeError: Ticket de Acceso vacio!
Traceback: Traceback (most recent call last):
  File "utils.pyc", line 152, in capturar_errores_wrapper
  File "utils.pyc", line 375, in SetTicketAcceso
RuntimeError: Ticket de Acceso vacio!

18-03-2016 , Version 2.10b HomologaciónInstallDir C:\PROGRA~1\PyAfipWs1.16d HomologaciónC:\PROGRA~1\PyAfipWsCodigo error afip:*****Numero de Error: 1429Mensaje de Error: Código de excepción OLE IDispatch 0 de Python COM Server Internal Error: Unexpected Python Error: Traceback (most recent call last):
  File "win32com\server\policy.pyc", line 277, in _Invoke_
  File "win32com\server\policy.pyc", line 282, in _invoke_
  File "win32com\server\policy.pyc", line 585, in _invokeex_
  File "utils.pyc", line 152, in capturar_errores_wrapper
  File "utils.pyc", line 375, in SetTicketAcceso
RuntimeError: Ticket de Acceso vacio!
Linea de codigo de error: wsfe.SetTicketAcceso(ta)Procedimiento: sw_conectarError VFP: Código de excepción OLE IDispatch 0 de Python COM Server Internal Error: Unexpected Python Error: Traceback (most recent call last):
  File "win32com\server\policy.pyc", line 277, in _Invoke_
  File "win32com\server\policy.pyc", line 282, in _invoke_
  File "win32com\server\policy.pyc", line 585, in _invokeex_
  File "utils.pyc", line 152, in capturar_errores_wrapper
  File "utils.pyc", line 375, in SetTicketAcceso
RuntimeError: Ticket de Acceso vacio!
.Exepción: RuntimeError: Ticket de Acceso vacio!
Traceback: Traceback (most recent call last):
  File "utils.pyc", line 152, in capturar_errores_wrapper
  File "utils.pyc", line 375, in SetTicketAcceso
RuntimeError: Ticket de Acceso vacio!

18-03-2016 , Version 2.10b HomologaciónInstallDir C:\PROGRA~1\PyAfipWs1.16d HomologaciónC:\PROGRA~1\PyAfipWsCodigo error afip:*****Numero de Error: 1429Mensaje de Error: Código de excepción OLE IDispatch 0 de Python COM Server Internal Error: Unexpected Python Error: Traceback (most recent call last):
  File "win32com\server\policy.pyc", line 277, in _Invoke_
  File "win32com\server\policy.pyc", line 282, in _invoke_
  File "win32com\server\policy.pyc", line 585, in _invokeex_
  File "utils.pyc", line 152, in capturar_errores_wrapper
  File "utils.pyc", line 375, in SetTicketAcceso
RuntimeError: Ticket de Acceso vacio!
Linea de codigo de error: wsfe.SetTicketAcceso(ta)Procedimiento: sw_conectarError VFP: Código de excepción OLE IDispatch 0 de Python COM Server Internal Error: Unexpected Python Error: Traceback (most recent call last):
  File "win32com\server\policy.pyc", line 277, in _Invoke_
  File "win32com\server\policy.pyc", line 282, in _invoke_
  File "win32com\server\policy.pyc", line 585, in _invokeex_
  File "utils.pyc", line 152, in capturar_errores_wrapper
  File "utils.pyc", line 375, in SetTicketAcceso
RuntimeError: Ticket de Acceso vacio!
.Exepción: RuntimeError: Ticket de Acceso vacio!
Traceback: Traceback (most recent call last):
  File "utils.pyc", line 152, in capturar_errores_wrapper
  File "utils.pyc", line 375, in SetTicketAcceso
RuntimeError: Ticket de Acceso vacio!

18-03-2016 , Version 2.10b HomologaciónInstallDir C:\PROGRA~1\PyAfipWs1.16d HomologaciónC:\PROGRA~1\PyAfipWsCodigo error afip:*****Numero de Error: 1429Mensaje de Error: Código de excepción OLE IDispatch 0 de Python COM Server Internal Error: Unexpected Python Error: Traceback (most recent call last):
  File "win32com\server\policy.pyc", line 277, in _Invoke_
  File "win32com\server\policy.pyc", line 282, in _invoke_
  File "win32com\server\policy.pyc", line 585, in _invokeex_
  File "utils.pyc", line 152, in capturar_errores_wrapper
  File "utils.pyc", line 375, in SetTicketAcceso
RuntimeError: Ticket de Acceso vacio!
Linea de codigo de error: wsfe.SetTicketAcceso(ta)Procedimiento: sw_conectarError VFP: Código de excepción OLE IDispatch 0 de Python COM Server Internal Error: Unexpected Python Error: Traceback (most recent call last):
  File "win32com\server\policy.pyc", line 277, in _Invoke_
  File "win32com\server\policy.pyc", line 282, in _invoke_
  File "win32com\server\policy.pyc", line 585, in _invokeex_
  File "utils.pyc", line 152, in capturar_errores_wrapper
  File "utils.pyc", line 375, in SetTicketAcceso
RuntimeError: Ticket de Acceso vacio!
.Exepción: RuntimeError: Ticket de Acceso vacio!
Traceback: Traceback (most recent call last):
  File "utils.pyc", line 152, in capturar_errores_wrapper
  File "utils.pyc", line 375, in SetTicketAcceso
RuntimeError: Ticket de Acceso vacio!

18-03-2016 , Version 2.10b HomologaciónInstallDir C:\PROGRA~1\PyAfipWs1.16d HomologaciónC:\PROGRA~1\PyAfipWsCodigo error afip:*****Numero de Error: 1429Mensaje de Error: Código de excepción OLE IDispatch 0 de Python COM Server Internal Error: Unexpected Python Error: Traceback (most recent call last):
  File "win32com\server\policy.pyc", line 277, in _Invoke_
  File "win32com\server\policy.pyc", line 282, in _invoke_
  File "win32com\server\policy.pyc", line 585, in _invokeex_
  File "utils.pyc", line 152, in capturar_errores_wrapper
  File "utils.pyc", line 375, in SetTicketAcceso
RuntimeError: Ticket de Acceso vacio!
Linea de codigo de error: wsfe.SetTicketAcceso(ta)Procedimiento: sw_conectarError VFP: Código de excepción OLE IDispatch 0 de Python COM Server Internal Error: Unexpected Python Error: Traceback (most recent call last):
  File "win32com\server\policy.pyc", line 277, in _Invoke_
  File "win32com\server\policy.pyc", line 282, in _invoke_
  File "win32com\server\policy.pyc", line 585, in _invokeex_
  File "utils.pyc", line 152, in capturar_errores_wrapper
  File "utils.pyc", line 375, in SetTicketAcceso
RuntimeError: Ticket de Acceso vacio!
.Exepción: RuntimeError: Ticket de Acceso vacio!
Traceback: Traceback (most recent call last):
  File "utils.pyc", line 152, in capturar_errores_wrapper
  File "utils.pyc", line 375, in SetTicketAcceso
RuntimeError: Ticket de Acceso vacio!

18-03-2016 , Version 2.10b HomologaciónInstallDir C:\PROGRA~1\PyAfipWs1.16d HomologaciónC:\PROGRA~1\PyAfipWsCodigo error afip:*****Numero de Error: 1429Mensaje de Error: Código de excepción OLE IDispatch 0 de Python COM Server Internal Error: Unexpected Python Error: Traceback (most recent call last):
  File "win32com\server\policy.pyc", line 277, in _Invoke_
  File "win32com\server\policy.pyc", line 282, in _invoke_
  File "win32com\server\policy.pyc", line 585, in _invokeex_
  File "utils.pyc", line 152, in capturar_errores_wrapper
  File "utils.pyc", line 375, in SetTicketAcceso
RuntimeError: Ticket de Acceso vacio!
Linea de codigo de error: wsfe.SetTicketAcceso(ta)Procedimiento: sw_conectarError VFP: Código de excepción OLE IDispatch 0 de Python COM Server Internal Error: Unexpected Python Error: Traceback (most recent call last):
  File "win32com\server\policy.pyc", line 277, in _Invoke_
  File "win32com\server\policy.pyc", line 282, in _invoke_
  File "win32com\server\policy.pyc", line 585, in _invokeex_
  File "utils.pyc", line 152, in capturar_errores_wrapper
  File "utils.pyc", line 375, in SetTicketAcceso
RuntimeError: Ticket de Acceso vacio!
.Exepción: RuntimeError: Ticket de Acceso vacio!
Traceback: Traceback (most recent call last):
  File "utils.pyc", line 152, in capturar_errores_wrapper
  File "utils.pyc", line 375, in SetTicketAcceso
RuntimeError: Ticket de Acceso vacio!

18-03-2016 , Version 2.10b HomologaciónInstallDir C:\PROGRA~1\PyAfipWs1.16d HomologaciónC:\PROGRA~1\PyAfipWsappserver status OKdbserver status OKauthserver status OKWSFE.CompUltimoAutorizado(1,27)600: ValidacionDeToken: No apareció CUIT en lista de relaciones: 20172716912
18-03-2016 , Version 2.10b HomologaciónInstallDir C:\PROGRA~1\PyAfipWs1.16d HomologaciónC:\PROGRA~1\PyAfipWsappserver status OKdbserver status OKauthserver status OKWSFE.CompUltimoAutorizado(1,27)600: ValidacionDeToken: No apareció CUIT en lista de relaciones: 20172716912
18-03-2016 , Version 2.10b HomologaciónInstallDir C:\PROGRA~1\PyAfipWs1.16d HomologaciónC:\PROGRA~1\PyAfipWsappserver status OKdbserver status OKauthserver status OKWSFE.CompUltimoAutorizado(1,27)Orden:110070: Si ImpNeto es mayor a 0 el objeto IVA es obligatorio.602: No existen datos en nuestros registros para los parametros ingresados.
18-03-2016 , Version 2.10b HomologaciónInstallDir C:\PROGRA~1\PyAfipWs1.16d HomologaciónC:\PROGRA~1\PyAfipWsappserver status OKdbserver status OKauthserver status OKWSFE.CompUltimoAutorizado(1,1)Orden:1265110070: Si ImpNeto es mayor a 0 el objeto IVA es obligatorio.602: No existen datos en nuestros registros para los parametros ingresados.
18-03-2016 , Version 2.10b HomologaciónInstallDir C:\PROGRA~1\PyAfipWs1.16d HomologaciónC:\PROGRA~1\PyAfipWsappserver status OKdbserver status OKauthserver status OKWSFE.CompUltimoAutorizado(1,1)Orden:1265110070: Si ImpNeto es mayor a 0 el objeto IVA es obligatorio.602: No existen datos en nuestros registros para los parametros ingresados.
18-03-2016 , Version 2.10b HomologaciónInstallDir C:\PROGRA~1\PyAfipWs1.16d HomologaciónC:\PROGRA~1\PyAfipWsappserver status OKdbserver status OKauthserver status OKWSFE.CompUltimoAutorizado(1,1)Server was unable to read request. ---> There is an error in XML document (5, 1536). ---> Input string was not in a correct format.
18-03-2016 , Version 2.10b HomologaciónInstallDir C:\PROGRA~1\PyAfipWs1.16d HomologaciónC:\PROGRA~1\PyAfipWsappserver status OKdbserver status OKauthserver status OKWSFE.CompUltimoAutorizado(1,1)Server was unable to read request. ---> There is an error in XML document (5, 1536). ---> Input string was not in a correct format.
18-03-2016 , Version 2.10b HomologaciónInstallDir C:\PROGRA~1\PyAfipWs1.16d HomologaciónC:\PROGRA~1\PyAfipWsappserver status OKdbserver status OKauthserver status OKWSFE.CompUltimoAutorizado(1,1)Server was unable to read request. ---> There is an error in XML document (5, 1536). ---> Input string was not in a correct format.
06-04-2016 , Version 2.10b HomologaciónInstallDir C:\PROGRA~1\PyAfipWs1.16d HomologaciónC:\PROGRA~1\PyAfipWsappserver status OKdbserver status OKauthserver status OKWSFE.CompUltimoAutorizado(1,1)Consultamos la fecha del ultimo comprobanteWSFE.CompConsultar(1,1,1)Fecha Ulti: 16-03-2016El CUIT consultado (20054940077)no coincide con el del comprobante (20169604747)602: No existen datos en nuestros registros para los parametros ingresados.
18-04-2016 , Version 2.10d InstallDir C:\PROGRA~1\PyAfipWs1.16d C:\PROGRA~1\PyAfipWsappserver status OKdbserver status OKauthserver status OKWSFE.CompUltimoAutorizado(1,3)Consultamos la fecha del ultimo comprobanteWSFE.CompConsultar(1,3,10)Fecha Ulti: 07-04-2016El CUIT consultado (20054940077)no coincide con el del comprobante (20169604747)
18-04-2016 , Version 2.10d InstallDir C:\PROGRA~1\PyAfipWs1.16d C:\PROGRA~1\PyAfipWsCodigo error afip:*****Numero de Error: 1429Mensaje de Error: Código de excepción OLE IDispatch 0 de Python COM Server Internal Error: Unexpected Python Error: Traceback (most recent call last):
  File "win32com\server\policy.pyc", line 277, in _Invoke_
  File "win32com\server\policy.pyc", line 282, in _invoke_
  File "win32com\server\policy.pyc", line 585, in _invokeex_
  File "utils.pyc", line 150, in capturar_errores_wrapper
  File "utils.pyc", line 377, in SetTicketAcceso
RuntimeError: Ticket de Acceso vacio!
Linea de codigo de error: wsfe.SetTicketAcceso(ta)Procedimiento: sw_conectarError VFP: Código de excepción OLE IDispatch 0 de Python COM Server Internal Error: Unexpected Python Error: Traceback (most recent call last):
  File "win32com\server\policy.pyc", line 277, in _Invoke_
  File "win32com\server\policy.pyc", line 282, in _invoke_
  File "win32com\server\policy.pyc", line 585, in _invokeex_
  File "utils.pyc", line 150, in capturar_errores_wrapper
  File "utils.pyc", line 377, in SetTicketAcceso
RuntimeError: Ticket de Acceso vacio!
.Exepción: RuntimeError: Ticket de Acceso vacio!
Traceback: Traceback (most recent call last):
  File "utils.pyc", line 150, in capturar_errores_wrapper
  File "utils.pyc", line 377, in SetTicketAcceso
RuntimeError: Ticket de Acceso vacio!

18-04-2016 , Version 2.10b HomologaciónInstallDir C:\PROGRA~1\PyAfipWs1.16d HomologaciónC:\PROGRA~1\PyAfipWsCodigo error afip:*****Numero de Error: 1429Mensaje de Error: Código de excepción OLE IDispatch 0 de Python COM Server Internal Error: Unexpected Python Error: Traceback (most recent call last):
  File "win32com\server\policy.pyc", line 277, in _Invoke_
  File "win32com\server\policy.pyc", line 282, in _invoke_
  File "win32com\server\policy.pyc", line 585, in _invokeex_
  File "utils.pyc", line 152, in capturar_errores_wrapper
  File "utils.pyc", line 375, in SetTicketAcceso
RuntimeError: Ticket de Acceso vacio!
Linea de codigo de error: wsfe.SetTicketAcceso(ta)Procedimiento: sw_conectarError VFP: Código de excepción OLE IDispatch 0 de Python COM Server Internal Error: Unexpected Python Error: Traceback (most recent call last):
  File "win32com\server\policy.pyc", line 277, in _Invoke_
  File "win32com\server\policy.pyc", line 282, in _invoke_
  File "win32com\server\policy.pyc", line 585, in _invokeex_
  File "utils.pyc", line 152, in capturar_errores_wrapper
  File "utils.pyc", line 375, in SetTicketAcceso
RuntimeError: Ticket de Acceso vacio!
.Exepción: RuntimeError: Ticket de Acceso vacio!
Traceback: Traceback (most recent call last):
  File "utils.pyc", line 152, in capturar_errores_wrapper
  File "utils.pyc", line 375, in SetTicketAcceso
RuntimeError: Ticket de Acceso vacio!

18-04-2016 , Version 2.10b HomologaciónInstallDir C:\PROGRA~1\PyAfipWs1.16d HomologaciónC:\PROGRA~1\PyAfipWsCodigo error afip:*****Numero de Error: 1429Mensaje de Error: Código de excepción OLE IDispatch 0 de Python COM Server Internal Error: Unexpected Python Error: Traceback (most recent call last):
  File "win32com\server\policy.pyc", line 277, in _Invoke_
  File "win32com\server\policy.pyc", line 282, in _invoke_
  File "win32com\server\policy.pyc", line 585, in _invokeex_
  File "utils.pyc", line 152, in capturar_errores_wrapper
  File "utils.pyc", line 375, in SetTicketAcceso
RuntimeError: Ticket de Acceso vacio!
Linea de codigo de error: wsfe.SetTicketAcceso(ta)Procedimiento: sw_conectarError VFP: Código de excepción OLE IDispatch 0 de Python COM Server Internal Error: Unexpected Python Error: Traceback (most recent call last):
  File "win32com\server\policy.pyc", line 277, in _Invoke_
  File "win32com\server\policy.pyc", line 282, in _invoke_
  File "win32com\server\policy.pyc", line 585, in _invokeex_
  File "utils.pyc", line 152, in capturar_errores_wrapper
  File "utils.pyc", line 375, in SetTicketAcceso
RuntimeError: Ticket de Acceso vacio!
.Exepción: RuntimeError: Ticket de Acceso vacio!
Traceback: Traceback (most recent call last):
  File "utils.pyc", line 152, in capturar_errores_wrapper
  File "utils.pyc", line 375, in SetTicketAcceso
RuntimeError: Ticket de Acceso vacio!

18-04-2016 , Version 2.10b HomologaciónInstallDir C:\PROGRA~1\PyAfipWs1.16d HomologaciónC:\PROGRA~1\PyAfipWsCodigo error afip:*****Numero de Error: 1429Mensaje de Error: Código de excepción OLE IDispatch 0 de Python COM Server Internal Error: Unexpected Python Error: Traceback (most recent call last):
  File "win32com\server\policy.pyc", line 277, in _Invoke_
  File "win32com\server\policy.pyc", line 282, in _invoke_
  File "win32com\server\policy.pyc", line 585, in _invokeex_
  File "utils.pyc", line 152, in capturar_errores_wrapper
  File "utils.pyc", line 375, in SetTicketAcceso
RuntimeError: Ticket de Acceso vacio!
Linea de codigo de error: wsfe.SetTicketAcceso(ta)Procedimiento: sw_conectarError VFP: Código de excepción OLE IDispatch 0 de Python COM Server Internal Error: Unexpected Python Error: Traceback (most recent call last):
  File "win32com\server\policy.pyc", line 277, in _Invoke_
  File "win32com\server\policy.pyc", line 282, in _invoke_
  File "win32com\server\policy.pyc", line 585, in _invokeex_
  File "utils.pyc", line 152, in capturar_errores_wrapper
  File "utils.pyc", line 375, in SetTicketAcceso
RuntimeError: Ticket de Acceso vacio!
.Exepción: RuntimeError: Ticket de Acceso vacio!
Traceback: Traceback (most recent call last):
  File "utils.pyc", line 152, in capturar_errores_wrapper
  File "utils.pyc", line 375, in SetTicketAcceso
RuntimeError: Ticket de Acceso vacio!

18-04-2016 , Version 2.10b HomologaciónInstallDir C:\PROGRA~1\PyAfipWs1.16d HomologaciónC:\PROGRA~1\PyAfipWsCodigo error afip:*****Numero de Error: 1429Mensaje de Error: Código de excepción OLE IDispatch 0 de Python COM Server Internal Error: Unexpected Python Error: Traceback (most recent call last):
  File "win32com\server\policy.pyc", line 277, in _Invoke_
  File "win32com\server\policy.pyc", line 282, in _invoke_
  File "win32com\server\policy.pyc", line 585, in _invokeex_
  File "utils.pyc", line 152, in capturar_errores_wrapper
  File "utils.pyc", line 375, in SetTicketAcceso
RuntimeError: Ticket de Acceso vacio!
Linea de codigo de error: wsfe.SetTicketAcceso(ta)Procedimiento: sw_conectarError VFP: Código de excepción OLE IDispatch 0 de Python COM Server Internal Error: Unexpected Python Error: Traceback (most recent call last):
  File "win32com\server\policy.pyc", line 277, in _Invoke_
  File "win32com\server\policy.pyc", line 282, in _invoke_
  File "win32com\server\policy.pyc", line 585, in _invokeex_
  File "utils.pyc", line 152, in capturar_errores_wrapper
  File "utils.pyc", line 375, in SetTicketAcceso
RuntimeError: Ticket de Acceso vacio!
.Exepción: RuntimeError: Ticket de Acceso vacio!
Traceback: Traceback (most recent call last):
  File "utils.pyc", line 152, in capturar_errores_wrapper
  File "utils.pyc", line 375, in SetTicketAcceso
RuntimeError: Ticket de Acceso vacio!

18-04-2016 , Version 2.10b HomologaciónInstallDir C:\PROGRA~1\PyAfipWs1.16d HomologaciónC:\PROGRA~1\PyAfipWsappserver status OKdbserver status OKauthserver status OKWSFE.CompUltimoAutorizado(1,3)Consultamos la fecha del ultimo comprobanteWSFE.CompConsultar(1,3,13)Fecha Ulti: 18-04-2016ERROR AL SOLICITARCAEEl nro de comprobante autorizado 2 ya se encontraba informado.El ultimo autorizado por Afip es 13El CUIT consultado (20054940077)no coincide con el del comprobante (20169604747)
06-05-2016 , Version 2.10b HomologaciónInstallDir C:\PROGRA~1\PyAfipWs1.16d HomologaciónC:\PROGRA~1\PyAfipWsappserver status OKdbserver status OKauthserver status OKWSFE.CompUltimoAutorizado(1,3)Consultamos la fecha del ultimo comprobanteWSFE.CompConsultar(1,3,15)Fecha Ulti: 18-04-2016Codigo error afip:0Numero de Error: 107Mensaje de Error: Linea de codigo de error: IF nImpTotal <> nTotalCompProcedimiento: robotconsul_procesoError VFP: Incompatibilidad entre el tipo de operador y el tipo de operando.Exepción: Traceback: 
06-05-2016 , Version 2.10b HomologaciónInstallDir C:\PROGRA~1\PyAfipWs1.16d HomologaciónC:\PROGRA~1\PyAfipWsappserver status OKdbserver status OKauthserver status OKWSFE.CompUltimoAutorizado(1,3)Consultamos la fecha del ultimo comprobanteWSFE.CompConsultar(1,3,15)Fecha Ulti: 18-04-2016WSFE.CompUltimoAutorizado(1,3)Consultamos la fecha del ultimo comprobanteWSFE.CompConsultar(1,3,15)Fecha Ulti: 18-04-2016Codigo error afip:0Numero de Error: 1734Mensaje de Error: PATHORIGENLinea de codigo de error: IF FILE(this.Pathorigen+cName+".CA0")Procedimiento: cambiarmoduloError VFP: No se encuentra la propiedad PATHORIGEN.Exepción: Traceback: 
06-05-2016 , Version 2.10b HomologaciónInstallDir C:\PROGRA~1\PyAfipWs1.16d HomologaciónC:\PROGRA~1\PyAfipWsappserver status OKdbserver status OKauthserver status OKWSFE.CompUltimoAutorizado(1,3)Consultamos la fecha del ultimo comprobanteWSFE.CompConsultar(1,3,15)Fecha Ulti: 18-04-2016WSFE.CompUltimoAutorizado(1,3)Consultamos la fecha del ultimo comprobanteWSFE.CompConsultar(1,3,15)Fecha Ulti: 18-04-2016Codigo error afip:0Numero de Error: 1924Mensaje de Error: PARENTLinea de codigo de error: IF FILE(this.Parent.Pathorigen+cName+".CA0")Procedimiento: cambiarmoduloError VFP: PARENT no es un objeto.Exepción: Traceback: 
02-08-2016 , Version 2.10b HomologaciónInstallDir C:\PROGRA~2\PyAfipWs1.16d HomologaciónC:\PROGRA~2\PyAfipWsappserver status OKdbserver status OKauthserver status OKWSFE.CompUltimoAutorizado(8,6)600: ValidacionDeToken: No apareció CUIT en lista de relaciones: 20054940077
02-08-2016 , Version 2.10b HomologaciónInstallDir C:\PROGRA~2\PyAfipWs1.16d HomologaciónC:\PROGRA~2\PyAfipWsappserver status OKdbserver status OKauthserver status OKWSFE.CompUltimoAutorizado(8,6)600: ValidacionDeToken: No apareció CUIT en lista de relaciones: 20054940077
02-08-2016 , Version 2.10b HomologaciónInstallDir C:\PROGRA~2\PyAfipWs1.16d HomologaciónC:\PROGRA~2\PyAfipWsappserver status OKdbserver status OKauthserver status OK
02-08-2016 , Version 2.10b HomologaciónInstallDir C:\PROGRA~2\PyAfipWs1.16d HomologaciónC:\PROGRA~2\PyAfipWsappserver status OKdbserver status OKauthserver status OKWSFE.CompUltimoAutorizado(8,6)600: ValidacionDeToken: No apareció CUIT en lista de relaciones: 20109445291
02-08-2016 , Version 2.10b HomologaciónInstallDir C:\PROGRA~2\PyAfipWs1.16d HomologaciónC:\PROGRA~2\PyAfipWsappserver status OKdbserver status OKauthserver status OKWSFE.CompUltimoAutorizado(8,6)600: ValidacionDeToken: No apareció CUIT en lista de relaciones: 20109445291
02-08-2016 , Version 2.10b HomologaciónInstallDir C:\PROGRA~2\PyAfipWs1.16d HomologaciónC:\PROGRA~2\PyAfipWsappserver status OKdbserver status OKauthserver status OKWSFE.CompUltimoAutorizado(8,6)600: ValidacionDeToken: No apareció CUIT en lista de relaciones: 20109445291
25-08-2016 , Version 2.10b HomologaciónInstallDir C:\PROGRA~1\PyAfipWs1.16d HomologaciónC:\PROGRA~1\PyAfipWsappserver status OKdbserver status OKauthserver status OKWSFE.CompUltimoAutorizado(1,3)Codigo error afip:*****Numero de Error: 1429Mensaje de Error: Código de excepción OLE IDispatch 0 de Python COM Server Internal Error: Unexpected Python Error: Traceback (most recent call last):
  File "win32com\server\policy.pyc", line 277, in _Invoke_
  File "win32com\server\policy.pyc", line 282, in _invoke_
  File "win32com\server\policy.pyc", line 585, in _invokeex_
  File "utils.pyc", line 152, in capturar_errores_wrapper
  File "wsfev1.pyc", line 303, in CompUltimoAutorizado
  File "wsfev1.pyc", line 111, in __analizar_errores
KeyError: 'code'
Linea de codigo de error: UltCBTE = WSFE.CompUltimoAutorizado(cTipoCbte, cPrefijo)Procedimiento: verifultcomp_dbfError VFP: Código de excepción OLE IDispatch 0 de Python COM Server Internal Error: Unexpected Python Error: Traceback (most recent call last):
  File "win32com\server\policy.pyc", line 277, in _Invoke_
  File "win32com\server\policy.pyc", line 282, in _invoke_
  File "win32com\server\policy.pyc", line 585, in _invokeex_
  File "utils.pyc", line 152, in capturar_errores_wrapper
  File "wsfev1.pyc", line 303, in CompUltimoAutorizado
  File "wsfev1.pyc", line 111, in __analizar_errores
KeyError: 'code'
.Exepción: KeyError: 'code'
Traceback: Traceback (most recent call last):
  File "utils.pyc", line 152, in capturar_errores_wrapper
  File "wsfev1.pyc", line 303, in CompUltimoAutorizado
  File "wsfev1.pyc", line 111, in __analizar_errores
KeyError: 'code'

25-08-2016 , Version 2.10b HomologaciónInstallDir C:\PROGRA~1\PyAfipWs1.16d HomologaciónC:\PROGRA~1\PyAfipWsappserver status OKdbserver status OKauthserver status OKWSFE.CompUltimoAutorizado(1,3)Codigo error afip:*****Numero de Error: 1429Mensaje de Error: Código de excepción OLE IDispatch 0 de Python COM Server Internal Error: Unexpected Python Error: Traceback (most recent call last):
  File "win32com\server\policy.pyc", line 277, in _Invoke_
  File "win32com\server\policy.pyc", line 282, in _invoke_
  File "win32com\server\policy.pyc", line 585, in _invokeex_
  File "utils.pyc", line 152, in capturar_errores_wrapper
  File "wsfev1.pyc", line 303, in CompUltimoAutorizado
  File "wsfev1.pyc", line 111, in __analizar_errores
KeyError: 'code'
Linea de codigo de error: UltCBTE = WSFE.CompUltimoAutorizado(cTipoCbte, cPrefijo)Procedimiento: verifultcomp_dbfError VFP: Código de excepción OLE IDispatch 0 de Python COM Server Internal Error: Unexpected Python Error: Traceback (most recent call last):
  File "win32com\server\policy.pyc", line 277, in _Invoke_
  File "win32com\server\policy.pyc", line 282, in _invoke_
  File "win32com\server\policy.pyc", line 585, in _invokeex_
  File "utils.pyc", line 152, in capturar_errores_wrapper
  File "wsfev1.pyc", line 303, in CompUltimoAutorizado
  File "wsfev1.pyc", line 111, in __analizar_errores
KeyError: 'code'
.Exepción: KeyError: 'code'
Traceback: Traceback (most recent call last):
  File "utils.pyc", line 152, in capturar_errores_wrapper
  File "wsfev1.pyc", line 303, in CompUltimoAutorizado
  File "wsfev1.pyc", line 111, in __analizar_errores
KeyError: 'code'

25-08-2016 , Version 2.10b HomologaciónInstallDir C:\PROGRA~1\PyAfipWs1.16d HomologaciónC:\PROGRA~1\PyAfipWsappserver status OKdbserver status OKauthserver status OKWSFE.CompUltimoAutorizado(1,3)Codigo error afip:*****Numero de Error: 1429Mensaje de Error: Código de excepción OLE IDispatch 0 de Python COM Server Internal Error: Unexpected Python Error: Traceback (most recent call last):
  File "win32com\server\policy.pyc", line 277, in _Invoke_
  File "win32com\server\policy.pyc", line 282, in _invoke_
  File "win32com\server\policy.pyc", line 585, in _invokeex_
  File "utils.pyc", line 152, in capturar_errores_wrapper
  File "wsfev1.pyc", line 303, in CompUltimoAutorizado
  File "wsfev1.pyc", line 111, in __analizar_errores
KeyError: 'code'
Linea de codigo de error: UltCBTE = WSFE.CompUltimoAutorizado(cTipoCbte, cPrefijo)Procedimiento: verifultcomp_dbfError VFP: Código de excepción OLE IDispatch 0 de Python COM Server Internal Error: Unexpected Python Error: Traceback (most recent call last):
  File "win32com\server\policy.pyc", line 277, in _Invoke_
  File "win32com\server\policy.pyc", line 282, in _invoke_
  File "win32com\server\policy.pyc", line 585, in _invokeex_
  File "utils.pyc", line 152, in capturar_errores_wrapper
  File "wsfev1.pyc", line 303, in CompUltimoAutorizado
  File "wsfev1.pyc", line 111, in __analizar_errores
KeyError: 'code'
.Exepción: KeyError: 'code'
Traceback: Traceback (most recent call last):
  File "utils.pyc", line 152, in capturar_errores_wrapper
  File "wsfev1.pyc", line 303, in CompUltimoAutorizado
  File "wsfev1.pyc", line 111, in __analizar_errores
KeyError: 'code'

25-08-2016 , Version 2.10b HomologaciónInstallDir C:\PROGRA~1\PyAfipWs1.16d HomologaciónC:\PROGRA~1\PyAfipWsappserver status OKdbserver status OKauthserver status OK
25-08-2016 , Version 2.10b HomologaciónInstallDir C:\PROGRA~1\PyAfipWs1.16d HomologaciónC:\PROGRA~1\PyAfipWsappserver status OKdbserver status OKauthserver status OKWSFE.CompUltimoAutorizado(1,6)Codigo error afip:*****Numero de Error: 1429Mensaje de Error: Código de excepción OLE IDispatch 0 de Python COM Server Internal Error: Unexpected Python Error: Traceback (most recent call last):
  File "win32com\server\policy.pyc", line 277, in _Invoke_
  File "win32com\server\policy.pyc", line 282, in _invoke_
  File "win32com\server\policy.pyc", line 585, in _invokeex_
  File "utils.pyc", line 152, in capturar_errores_wrapper
  File "wsfev1.pyc", line 303, in CompUltimoAutorizado
  File "wsfev1.pyc", line 111, in __analizar_errores
KeyError: 'code'
Linea de codigo de error: UltCBTE = WSFE.CompUltimoAutorizado(cTipoCbte, cPrefijo)Procedimiento: verifultcomp_dbfError VFP: Código de excepción OLE IDispatch 0 de Python COM Server Internal Error: Unexpected Python Error: Traceback (most recent call last):
  File "win32com\server\policy.pyc", line 277, in _Invoke_
  File "win32com\server\policy.pyc", line 282, in _invoke_
  File "win32com\server\policy.pyc", line 585, in _invokeex_
  File "utils.pyc", line 152, in capturar_errores_wrapper
  File "wsfev1.pyc", line 303, in CompUltimoAutorizado
  File "wsfev1.pyc", line 111, in __analizar_errores
KeyError: 'code'
.Exepción: KeyError: 'code'
Traceback: Traceback (most recent call last):
  File "utils.pyc", line 152, in capturar_errores_wrapper
  File "wsfev1.pyc", line 303, in CompUltimoAutorizado
  File "wsfev1.pyc", line 111, in __analizar_errores
KeyError: 'code'

25-08-2016 , Version 2.10b HomologaciónInstallDir C:\PROGRA~1\PyAfipWs1.16d HomologaciónC:\PROGRA~1\PyAfipWsappserver status OKdbserver status OKauthserver status OKWSFE.CompUltimoAutorizado(1,6)Codigo error afip:*****Numero de Error: 1429Mensaje de Error: Código de excepción OLE IDispatch 0 de Python COM Server Internal Error: Unexpected Python Error: Traceback (most recent call last):
  File "win32com\server\policy.pyc", line 277, in _Invoke_
  File "win32com\server\policy.pyc", line 282, in _invoke_
  File "win32com\server\policy.pyc", line 585, in _invokeex_
  File "utils.pyc", line 152, in capturar_errores_wrapper
  File "wsfev1.pyc", line 303, in CompUltimoAutorizado
  File "wsfev1.pyc", line 111, in __analizar_errores
KeyError: 'code'
Linea de codigo de error: UltCBTE = WSFE.CompUltimoAutorizado(cTipoCbte, cPrefijo)Procedimiento: verifultcomp_dbfError VFP: Código de excepción OLE IDispatch 0 de Python COM Server Internal Error: Unexpected Python Error: Traceback (most recent call last):
  File "win32com\server\policy.pyc", line 277, in _Invoke_
  File "win32com\server\policy.pyc", line 282, in _invoke_
  File "win32com\server\policy.pyc", line 585, in _invokeex_
  File "utils.pyc", line 152, in capturar_errores_wrapper
  File "wsfev1.pyc", line 303, in CompUltimoAutorizado
  File "wsfev1.pyc", line 111, in __analizar_errores
KeyError: 'code'
.Exepción: KeyError: 'code'
Traceback: Traceback (most recent call last):
  File "utils.pyc", line 152, in capturar_errores_wrapper
  File "wsfev1.pyc", line 303, in CompUltimoAutorizado
  File "wsfev1.pyc", line 111, in __analizar_errores
KeyError: 'code'

25-08-2016 , Version 2.10b HomologaciónInstallDir C:\PROGRA~1\PyAfipWs1.16d HomologaciónC:\PROGRA~1\PyAfipWsappserver status OKdbserver status OKauthserver status OKWSFE.CompUltimoAutorizado(1,6)Codigo error afip:*****Numero de Error: 1429Mensaje de Error: Código de excepción OLE IDispatch 0 de Python COM Server Internal Error: Unexpected Python Error: Traceback (most recent call last):
  File "win32com\server\policy.pyc", line 277, in _Invoke_
  File "win32com\server\policy.pyc", line 282, in _invoke_
  File "win32com\server\policy.pyc", line 585, in _invokeex_
  File "utils.pyc", line 152, in capturar_errores_wrapper
  File "wsfev1.pyc", line 303, in CompUltimoAutorizado
  File "wsfev1.pyc", line 111, in __analizar_errores
KeyError: 'code'
Linea de codigo de error: UltCBTE = WSFE.CompUltimoAutorizado(cTipoCbte, cPrefijo)Procedimiento: verifultcomp_dbfError VFP: Código de excepción OLE IDispatch 0 de Python COM Server Internal Error: Unexpected Python Error: Traceback (most recent call last):
  File "win32com\server\policy.pyc", line 277, in _Invoke_
  File "win32com\server\policy.pyc", line 282, in _invoke_
  File "win32com\server\policy.pyc", line 585, in _invokeex_
  File "utils.pyc", line 152, in capturar_errores_wrapper
  File "wsfev1.pyc", line 303, in CompUltimoAutorizado
  File "wsfev1.pyc", line 111, in __analizar_errores
KeyError: 'code'
.Exepción: KeyError: 'code'
Traceback: Traceback (most recent call last):
  File "utils.pyc", line 152, in capturar_errores_wrapper
  File "wsfev1.pyc", line 303, in CompUltimoAutorizado
  File "wsfev1.pyc", line 111, in __analizar_errores
KeyError: 'code'

25-08-2016 , Version 2.10b HomologaciónInstallDir C:\PROGRA~1\PyAfipWs1.16d HomologaciónC:\PROGRA~1\PyAfipWsappserver status OKdbserver status OKauthserver status OKWSFE.CompUltimoAutorizado(1,6)Codigo error afip:*****Numero de Error: 1429Mensaje de Error: Código de excepción OLE IDispatch 0 de Python COM Server Internal Error: Unexpected Python Error: Traceback (most recent call last):
  File "win32com\server\policy.pyc", line 277, in _Invoke_
  File "win32com\server\policy.pyc", line 282, in _invoke_
  File "win32com\server\policy.pyc", line 585, in _invokeex_
  File "utils.pyc", line 152, in capturar_errores_wrapper
  File "wsfev1.pyc", line 303, in CompUltimoAutorizado
  File "wsfev1.pyc", line 111, in __analizar_errores
KeyError: 'code'
Linea de codigo de error: UltCBTE = WSFE.CompUltimoAutorizado(cTipoCbte, cPrefijo)Procedimiento: verifultcomp_dbfError VFP: Código de excepción OLE IDispatch 0 de Python COM Server Internal Error: Unexpected Python Error: Traceback (most recent call last):
  File "win32com\server\policy.pyc", line 277, in _Invoke_
  File "win32com\server\policy.pyc", line 282, in _invoke_
  File "win32com\server\policy.pyc", line 585, in _invokeex_
  File "utils.pyc", line 152, in capturar_errores_wrapper
  File "wsfev1.pyc", line 303, in CompUltimoAutorizado
  File "wsfev1.pyc", line 111, in __analizar_errores
KeyError: 'code'
.Exepción: KeyError: 'code'
Traceback: Traceback (most recent call last):
  File "utils.pyc", line 152, in capturar_errores_wrapper
  File "wsfev1.pyc", line 303, in CompUltimoAutorizado
  File "wsfev1.pyc", line 111, in __analizar_errores
KeyError: 'code'

25-08-2016 , Version 2.10b HomologaciónInstallDir C:\PROGRA~1\PyAfipWsCodigo error afip:0Numero de Error: 1429Mensaje de Error: Código de excepción OLE IDispatch 0 de Python COM Server Internal Error: Unexpected Python Error: Traceback (most recent call last):
  File "win32com\server\policy.pyc", line 277, in _Invoke_
  File "win32com\server\policy.pyc", line 282, in _invoke_
  File "win32com\server\policy.pyc", line 585, in _invokeex_
  File "utils.pyc", line 152, in capturar_errores_wrapper
  File "wsaa.pyc", line 224, in SignTRA
  File "wsaa.pyc", line 94, in sign_tra
  File "M2Crypto\SMIME.pyc", line 204, in sign
SMIME_Error: 9976:error:0B080074:x509 certificate routines:X509_check_private_key:key values mismatch:.\crypto\x509\x509_cmp.c:330:
9976:error:2108907F:PKCS7 routines:PKCS7_sign_add_signer:private key does not match certificate:.\crypto\pkcs7\pk7_smime.c:170:
9976:error:21074099:PKCS7 routines:PKCS7_sign:pkcs7 add signer error:.\crypto\pkcs7\pk7_smime.c:88:

Linea de codigo de error: cms = WSAA.SignTRA(tra, cruta + this.hcrt, cruta + this.hkey)Procedimiento: sw_iniciarError VFP: Código de excepción OLE IDispatch 0 de Python COM Server Internal Error: Unexpected Python Error: Traceback (most recent call last):
  File "win32com\server\policy.pyc", line 277, in _Invoke_
  File "win32com\server\policy.pyc", line 282, in _invoke_
  File "win32com\server\policy.pyc", line 585, in _invokeex_
  File "utils.pyc", line 152, in capturar_errores_wrapper
  File "wsaa.pyc", line 224, in SignTRA
  File "wsaa.pyc", line 94, in sign_tra
  File "M2Crypto\SMIME.pyc", line 204, in sign
SMIME_Error: 9976:error:0B080074:x509 certificate routines:X509_check_private_key:key values mismatch:.\crypto\x509\x509_cmp.c:330:
9976:error:2108907F:PKCS7 routines:PKCS7_sign_add_signer:private key does not match certificate:.\crypto\pkcs7\pk7_smime.c:170:
9976:error:21074099:PKCS7 routines:PKCS7_sign:pkcs7 add signer error:.\crypto\pkcs7\pk7_smime.c:88:

.Exepción: SMIME_Error: 9976:error:0B080074:x509 certificate routines:X509_check_private_key:key values mismatch:.\crypto\x509\x509_cmp.c:330:
9976:error:2108907F:PKCS7 routines:PKCS7_sign_add_signer:private key does not match certificate:.\crypto\pkcs7\pk7_smime.c:170:
9976:error:21074099:PKCS7 routines:PKCS7_sign:pkcs7 add signer error:.\crypto\pkcs7\pk7_smime.c:88:

Traceback: Traceback (most recent call last):
  File "utils.pyc", line 152, in capturar_errores_wrapper
  File "wsaa.pyc", line 224, in SignTRA
  File "wsaa.pyc", line 94, in sign_tra
  File "M2Crypto\SMIME.pyc", line 204, in sign
SMIME_Error: 9976:error:0B080074:x509 certificate routines:X509_check_private_key:key values mismatch:.\crypto\x509\x509_cmp.c:330:
9976:error:2108907F:PKCS7 routines:PKCS7_sign_add_signer:private key does not match certificate:.\crypto\pkcs7\pk7_smime.c:170:
9976:error:21074099:PKCS7 routines:PKCS7_sign:pkcs7 add signer error:.\crypto\pkcs7\pk7_smime.c:88:


25-08-2016 , Version 2.10b HomologaciónInstallDir C:\PROGRA~1\PyAfipWs1.16d HomologaciónC:\PROGRA~1\PyAfipWsappserver status OKdbserver status OKauthserver status OKWSFE.CompUltimoAutorizado(1,6)Codigo error afip:*****Numero de Error: 1429Mensaje de Error: Código de excepción OLE IDispatch 0 de Python COM Server Internal Error: Unexpected Python Error: Traceback (most recent call last):
  File "win32com\server\policy.pyc", line 277, in _Invoke_
  File "win32com\server\policy.pyc", line 282, in _invoke_
  File "win32com\server\policy.pyc", line 585, in _invokeex_
  File "utils.pyc", line 152, in capturar_errores_wrapper
  File "wsfev1.pyc", line 303, in CompUltimoAutorizado
  File "wsfev1.pyc", line 111, in __analizar_errores
KeyError: 'code'
Linea de codigo de error: UltCBTE = WSFE.CompUltimoAutorizado(cTipoCbte, cPrefijo)Procedimiento: verifultcomp_dbfError VFP: Código de excepción OLE IDispatch 0 de Python COM Server Internal Error: Unexpected Python Error: Traceback (most recent call last):
  File "win32com\server\policy.pyc", line 277, in _Invoke_
  File "win32com\server\policy.pyc", line 282, in _invoke_
  File "win32com\server\policy.pyc", line 585, in _invokeex_
  File "utils.pyc", line 152, in capturar_errores_wrapper
  File "wsfev1.pyc", line 303, in CompUltimoAutorizado
  File "wsfev1.pyc", line 111, in __analizar_errores
KeyError: 'code'
.Exepción: KeyError: 'code'
Traceback: Traceback (most recent call last):
  File "utils.pyc", line 152, in capturar_errores_wrapper
  File "wsfev1.pyc", line 303, in CompUltimoAutorizado
  File "wsfev1.pyc", line 111, in __analizar_errores
KeyError: 'code'

26-08-2016 , Version 2.10d InstallDir C:\PROGRA~2\PyAfipWs1.16d C:\PROGRA~2\PyAfipWsappserver status OKdbserver status OKauthserver status OKWSFE.CompUltimoAutorizado(1,6)Codigo error afip:*****Numero de Error: 1429Mensaje de Error: Código de excepción OLE IDispatch 0 de Python COM Server Internal Error: Unexpected Python Error: Traceback (most recent call last):
  File "win32com\server\policy.pyc", line 277, in _Invoke_
  File "win32com\server\policy.pyc", line 282, in _invoke_
  File "win32com\server\policy.pyc", line 585, in _invokeex_
  File "utils.pyc", line 150, in capturar_errores_wrapper
  File "wsfev1.pyc", line 303, in CompUltimoAutorizado
  File "wsfev1.pyc", line 111, in __analizar_errores
KeyError: 'code'
Linea de codigo de error: UltCBTE = WSFE.CompUltimoAutorizado(cTipoCbte, cPrefijo)Procedimiento: verifultcomp_dbfError VFP: Código de excepción OLE IDispatch 0 de Python COM Server Internal Error: Unexpected Python Error: Traceback (most recent call last):
  File "win32com\server\policy.pyc", line 277, in _Invoke_
  File "win32com\server\policy.pyc", line 282, in _invoke_
  File "win32com\server\policy.pyc", line 585, in _invokeex_
  File "utils.pyc", line 150, in capturar_errores_wrapper
  File "wsfev1.pyc", line 303, in CompUltimoAutorizado
  File "wsfev1.pyc", line 111, in __analizar_errores
KeyError: 'code'
.Exepción: KeyError: 'code'
Traceback: Traceback (most recent call last):
  File "utils.pyc", line 150, in capturar_errores_wrapper
  File "wsfev1.pyc", line 303, in CompUltimoAutorizado
  File "wsfev1.pyc", line 111, in __analizar_errores
KeyError: 'code'

26-08-2016 , Version 2.10b HomologaciónInstallDir C:\PROGRA~2\PyAfipWs1.16d HomologaciónC:\PROGRA~2\PyAfipWsappserver status OKdbserver status OKauthserver status OKWSFE.CompUltimoAutorizado(1,6)Codigo error afip:*****Numero de Error: 1429Mensaje de Error: Código de excepción OLE IDispatch 0 de Python COM Server Internal Error: Unexpected Python Error: Traceback (most recent call last):
  File "win32com\server\policy.pyc", line 277, in _Invoke_
  File "win32com\server\policy.pyc", line 282, in _invoke_
  File "win32com\server\policy.pyc", line 585, in _invokeex_
  File "utils.pyc", line 152, in capturar_errores_wrapper
  File "wsfev1.pyc", line 303, in CompUltimoAutorizado
  File "wsfev1.pyc", line 111, in __analizar_errores
KeyError: 'code'
Linea de codigo de error: UltCBTE = WSFE.CompUltimoAutorizado(cTipoCbte, cPrefijo)Procedimiento: verifultcomp_dbfError VFP: Código de excepción OLE IDispatch 0 de Python COM Server Internal Error: Unexpected Python Error: Traceback (most recent call last):
  File "win32com\server\policy.pyc", line 277, in _Invoke_
  File "win32com\server\policy.pyc", line 282, in _invoke_
  File "win32com\server\policy.pyc", line 585, in _invokeex_
  File "utils.pyc", line 152, in capturar_errores_wrapper
  File "wsfev1.pyc", line 303, in CompUltimoAutorizado
  File "wsfev1.pyc", line 111, in __analizar_errores
KeyError: 'code'
.Exepción: KeyError: 'code'
Traceback: Traceback (most recent call last):
  File "utils.pyc", line 152, in capturar_errores_wrapper
  File "wsfev1.pyc", line 303, in CompUltimoAutorizado
  File "wsfev1.pyc", line 111, in __analizar_errores
KeyError: 'code'

26-08-2016 , Version 2.10b HomologaciónInstallDir C:\PROGRA~2\PyAfipWs1.16d HomologaciónC:\PROGRA~2\PyAfipWsappserver status OKdbserver status OKauthserver status OKWSFE.CompUltimoAutorizado(1,6)Codigo error afip:*****Numero de Error: 1429Mensaje de Error: Código de excepción OLE IDispatch 0 de Python COM Server Internal Error: Unexpected Python Error: Traceback (most recent call last):
  File "win32com\server\policy.pyc", line 277, in _Invoke_
  File "win32com\server\policy.pyc", line 282, in _invoke_
  File "win32com\server\policy.pyc", line 585, in _invokeex_
  File "utils.pyc", line 152, in capturar_errores_wrapper
  File "wsfev1.pyc", line 303, in CompUltimoAutorizado
  File "wsfev1.pyc", line 111, in __analizar_errores
KeyError: 'code'
Linea de codigo de error: UltCBTE = WSFE.CompUltimoAutorizado(cTipoCbte, cPrefijo)Procedimiento: verifultcomp_dbfError VFP: Código de excepción OLE IDispatch 0 de Python COM Server Internal Error: Unexpected Python Error: Traceback (most recent call last):
  File "win32com\server\policy.pyc", line 277, in _Invoke_
  File "win32com\server\policy.pyc", line 282, in _invoke_
  File "win32com\server\policy.pyc", line 585, in _invokeex_
  File "utils.pyc", line 152, in capturar_errores_wrapper
  File "wsfev1.pyc", line 303, in CompUltimoAutorizado
  File "wsfev1.pyc", line 111, in __analizar_errores
KeyError: 'code'
.Exepción: KeyError: 'code'
Traceback: Traceback (most recent call last):
  File "utils.pyc", line 152, in capturar_errores_wrapper
  File "wsfev1.pyc", line 303, in CompUltimoAutorizado
  File "wsfev1.pyc", line 111, in __analizar_errores
KeyError: 'code'

26-08-2016 , Version 2.10b HomologaciónInstallDir C:\PROGRA~2\PyAfipWs1.16d HomologaciónC:\PROGRA~2\PyAfipWsappserver status OKdbserver status OKauthserver status OKWSFE.CompUltimoAutorizado(1,6)Codigo error afip:*****Numero de Error: 1429Mensaje de Error: Código de excepción OLE IDispatch 0 de Python COM Server Internal Error: Unexpected Python Error: Traceback (most recent call last):
  File "win32com\server\policy.pyc", line 277, in _Invoke_
  File "win32com\server\policy.pyc", line 282, in _invoke_
  File "win32com\server\policy.pyc", line 585, in _invokeex_
  File "utils.pyc", line 152, in capturar_errores_wrapper
  File "wsfev1.pyc", line 303, in CompUltimoAutorizado
  File "wsfev1.pyc", line 111, in __analizar_errores
KeyError: 'code'
Linea de codigo de error: UltCBTE = WSFE.CompUltimoAutorizado(cTipoCbte, cPrefijo)Procedimiento: verifultcomp_dbfError VFP: Código de excepción OLE IDispatch 0 de Python COM Server Internal Error: Unexpected Python Error: Traceback (most recent call last):
  File "win32com\server\policy.pyc", line 277, in _Invoke_
  File "win32com\server\policy.pyc", line 282, in _invoke_
  File "win32com\server\policy.pyc", line 585, in _invokeex_
  File "utils.pyc", line 152, in capturar_errores_wrapper
  File "wsfev1.pyc", line 303, in CompUltimoAutorizado
  File "wsfev1.pyc", line 111, in __analizar_errores
KeyError: 'code'
.Exepción: KeyError: 'code'
Traceback: Traceback (most recent call last):
  File "utils.pyc", line 152, in capturar_errores_wrapper
  File "wsfev1.pyc", line 303, in CompUltimoAutorizado
  File "wsfev1.pyc", line 111, in __analizar_errores
KeyError: 'code'

26-08-2016 , Version 2.10b HomologaciónInstallDir C:\PROGRA~2\PyAfipWs1.16d HomologaciónC:\PROGRA~2\PyAfipWsappserver status OKdbserver status OKauthserver status OKWSFE.CompUltimoAutorizado(1,6)Codigo error afip:*****Numero de Error: 1429Mensaje de Error: Código de excepción OLE IDispatch 0 de Python COM Server Internal Error: Unexpected Python Error: Traceback (most recent call last):
  File "win32com\server\policy.pyc", line 277, in _Invoke_
  File "win32com\server\policy.pyc", line 282, in _invoke_
  File "win32com\server\policy.pyc", line 585, in _invokeex_
  File "utils.pyc", line 152, in capturar_errores_wrapper
  File "wsfev1.pyc", line 303, in CompUltimoAutorizado
  File "wsfev1.pyc", line 111, in __analizar_errores
KeyError: 'code'
Linea de codigo de error: UltCBTE = WSFE.CompUltimoAutorizado(cTipoCbte, cPrefijo)Procedimiento: verifultcomp_dbfError VFP: Código de excepción OLE IDispatch 0 de Python COM Server Internal Error: Unexpected Python Error: Traceback (most recent call last):
  File "win32com\server\policy.pyc", line 277, in _Invoke_
  File "win32com\server\policy.pyc", line 282, in _invoke_
  File "win32com\server\policy.pyc", line 585, in _invokeex_
  File "utils.pyc", line 152, in capturar_errores_wrapper
  File "wsfev1.pyc", line 303, in CompUltimoAutorizado
  File "wsfev1.pyc", line 111, in __analizar_errores
KeyError: 'code'
.Exepción: KeyError: 'code'
Traceback: Traceback (most recent call last):
  File "utils.pyc", line 152, in capturar_errores_wrapper
  File "wsfev1.pyc", line 303, in CompUltimoAutorizado
  File "wsfev1.pyc", line 111, in __analizar_errores
KeyError: 'code'

26-08-2016 , Version 2.10b HomologaciónInstallDir C:\PROGRA~2\PyAfipWs1.16d HomologaciónC:\PROGRA~2\PyAfipWsappserver status OKdbserver status OKauthserver status OKWSFE.CompUltimoAutorizado(1,6)Codigo error afip:*****Numero de Error: 1429Mensaje de Error: Código de excepción OLE IDispatch 0 de Python COM Server Internal Error: Unexpected Python Error: Traceback (most recent call last):
  File "win32com\server\policy.pyc", line 277, in _Invoke_
  File "win32com\server\policy.pyc", line 282, in _invoke_
  File "win32com\server\policy.pyc", line 585, in _invokeex_
  File "utils.pyc", line 152, in capturar_errores_wrapper
  File "wsfev1.pyc", line 303, in CompUltimoAutorizado
  File "wsfev1.pyc", line 111, in __analizar_errores
KeyError: 'code'
Linea de codigo de error: UltCBTE = WSFE.CompUltimoAutorizado(cTipoCbte, cPrefijo)Procedimiento: verifultcomp_dbfError VFP: Código de excepción OLE IDispatch 0 de Python COM Server Internal Error: Unexpected Python Error: Traceback (most recent call last):
  File "win32com\server\policy.pyc", line 277, in _Invoke_
  File "win32com\server\policy.pyc", line 282, in _invoke_
  File "win32com\server\policy.pyc", line 585, in _invokeex_
  File "utils.pyc", line 152, in capturar_errores_wrapper
  File "wsfev1.pyc", line 303, in CompUltimoAutorizado
  File "wsfev1.pyc", line 111, in __analizar_errores
KeyError: 'code'
.Exepción: KeyError: 'code'
Traceback: Traceback (most recent call last):
  File "utils.pyc", line 152, in capturar_errores_wrapper
  File "wsfev1.pyc", line 303, in CompUltimoAutorizado
  File "wsfev1.pyc", line 111, in __analizar_errores
KeyError: 'code'

26-08-2016 , Version 2.10b HomologaciónInstallDir C:\PROGRA~2\PyAfipWs1.16d HomologaciónC:\PROGRA~2\PyAfipWsappserver status OKdbserver status OKauthserver status OKWSFE.CompUltimoAutorizado(1,6)Codigo error afip:*****Numero de Error: 1429Mensaje de Error: Código de excepción OLE IDispatch 0 de Python COM Server Internal Error: Unexpected Python Error: Traceback (most recent call last):
  File "win32com\server\policy.pyc", line 277, in _Invoke_
  File "win32com\server\policy.pyc", line 282, in _invoke_
  File "win32com\server\policy.pyc", line 585, in _invokeex_
  File "utils.pyc", line 152, in capturar_errores_wrapper
  File "wsfev1.pyc", line 303, in CompUltimoAutorizado
  File "wsfev1.pyc", line 111, in __analizar_errores
KeyError: 'code'
Linea de codigo de error: UltCBTE = WSFE.CompUltimoAutorizado(cTipoCbte, cPrefijo)Procedimiento: verifultcomp_dbfError VFP: Código de excepción OLE IDispatch 0 de Python COM Server Internal Error: Unexpected Python Error: Traceback (most recent call last):
  File "win32com\server\policy.pyc", line 277, in _Invoke_
  File "win32com\server\policy.pyc", line 282, in _invoke_
  File "win32com\server\policy.pyc", line 585, in _invokeex_
  File "utils.pyc", line 152, in capturar_errores_wrapper
  File "wsfev1.pyc", line 303, in CompUltimoAutorizado
  File "wsfev1.pyc", line 111, in __analizar_errores
KeyError: 'code'
.Exepción: TypeError: SetTicketAcceso() takes exactly 2 arguments (1 given)
Traceback: Traceback (most recent call last):
  File "utils.pyc", line 152, in capturar_errores_wrapper
TypeError: SetTicketAcceso() takes exactly 2 arguments (1 given)

26-08-2016 , Version 2.10b HomologaciónInstallDir C:\PROGRA~2\PyAfipWs1.16d HomologaciónC:\PROGRA~2\PyAfipWsappserver status OKdbserver status OKauthserver status OKWSFE.CompUltimoAutorizado(1,6)Codigo error afip:*****Numero de Error: 1429Mensaje de Error: 80029c4a: Error loading type library/DLLLinea de codigo de error: UltCBTE = WSFE.CompUltimoAutorizado(cTipoCbte, cPrefijo)Procedimiento: verifultcomp_dbfError VFP: Código de excepción OLE IDispatch 0 de Python COM Server Internal Error: Unexpected Python Error: Traceback (most recent call last):
  File "win32com\server\policy.pyc", line 277, in _Invoke_
  File "win32com\server\policy.pyc", line 282, in _invoke_
  File "win32com\server\policy.pyc", line 585, in _invokeex_
  File "utils.pyc", line 152, in capturar_errores_wrapper
  File "wsfev1.pyc", line 303, in CompUltimoAutorizado
  File "wsfev1.pyc", line 111, in __analizar_errores
KeyError: 'code'
.Exepción: KeyError: 'code'
Traceback: Traceback (most recent call last):
  File "utils.pyc", line 152, in capturar_errores_wrapper
  File "wsfev1.pyc", line 303, in CompUltimoAutorizado
  File "wsfev1.pyc", line 111, in __analizar_errores
KeyError: 'code'

26-08-2016 , Version 2.10b HomologaciónInstallDir C:\PROGRA~2\PyAfipWs1.16d HomologaciónC:\PROGRA~2\PyAfipWsappserver status OKdbserver status OKauthserver status OKWSFE.CompUltimoAutorizado(1,6)Codigo error afip:*****Numero de Error: 1429Mensaje de Error: Código de excepción OLE IDispatch 0 de Python COM Server Internal Error: Unexpected Python Error: Traceback (most recent call last):
  File "win32com\server\policy.pyc", line 277, in _Invoke_
  File "win32com\server\policy.pyc", line 282, in _invoke_
  File "win32com\server\policy.pyc", line 585, in _invokeex_
  File "utils.pyc", line 152, in capturar_errores_wrapper
  File "wsfev1.pyc", line 303, in CompUltimoAutorizado
  File "wsfev1.pyc", line 111, in __analizar_errores
KeyError: 'code'
Linea de codigo de error: UltCBTE = WSFE.CompUltimoAutorizado(cTipoCbte, cPrefijo)Procedimiento: verifultcomp_dbfError VFP: Código de excepción OLE IDispatch 0 de Python COM Server Internal Error: Unexpected Python Error: Traceback (most recent call last):
  File "win32com\server\policy.pyc", line 277, in _Invoke_
  File "win32com\server\policy.pyc", line 282, in _invoke_
  File "win32com\server\policy.pyc", line 585, in _invokeex_
  File "utils.pyc", line 152, in capturar_errores_wrapper
  File "wsfev1.pyc", line 303, in CompUltimoAutorizado
  File "wsfev1.pyc", line 111, in __analizar_errores
KeyError: 'code'
.Exepción: KeyError: 'code'
Traceback: Traceback (most recent call last):
  File "utils.pyc", line 152, in capturar_errores_wrapper
  File "wsfev1.pyc", line 303, in CompUltimoAutorizado
  File "wsfev1.pyc", line 111, in __analizar_errores
KeyError: 'code'

26-08-2016 , Version 2.10b HomologaciónInstallDir C:\PROGRA~2\PyAfipWs1.16d HomologaciónC:\PROGRA~2\PyAfipWsappserver status OKdbserver status OKauthserver status OKWSFE.CompUltimoAutorizado(1,6)Codigo error afip:*****Numero de Error: 1429Linea de codigo de error: UltCBTE = WSFE.CompUltimoAutorizado(cTipoCbte, cPrefijo)Procedimiento: verifultcomp_dbfError VFP: Código de excepción OLE IDispatch 0 de Python COM Server Internal Error: Unexpected Python Error: Traceback (most recent call last):
  File "win32com\server\policy.pyc", line 277, in _Invoke_
  File "win32com\server\policy.pyc", line 282, in _invoke_
  File "win32com\server\policy.pyc", line 585, in _invokeex_
  File "utils.pyc", line 152, in capturar_errores_wrapper
  File "wsfev1.pyc", line 303, in CompUltimoAutorizado
  File "wsfev1.pyc", line 111, in __analizar_errores
KeyError: 'code'
.Exepción: KeyError: 'code'
Traceback: Traceback (most recent call last):
  File "utils.pyc", line 152, in capturar_errores_wrapper
  File "wsfev1.pyc", line 303, in CompUltimoAutorizado
  File "wsfev1.pyc", line 111, in __analizar_errores
KeyError: 'code'

18-10-2018 , Version 2.11a InstallDir C:\PyAfipWs1.18a C:\PyAfipWsCodigo error afip:*****Numero de Error: 1429Linea de codigo de error: ok = WSFE.Conectar("",url_wsdl,"",wrapper)      && HomologaciÃ³nProcedimiento: sw_conectarError VFP: Código de excepción OLE IDispatch 0 de Python COM Server Internal Error: Unexpected Python Error: Traceback (most recent call last):
  File "win32com\server\policy.pyc", line 277, in _Invoke_
  File "win32com\server\policy.pyc", line 282, in _invoke_
  File "win32com\server\policy.pyc", line 585, in _invokeex_
  File "utils.pyc", line 226, in Conectar
  File "pysimplesoap\transport.pyc", line 257, in set_http_wrapper
  File "pysimplesoap\transport.pyc", line 228, in get_http_wrapper
RuntimeError: pycurl transport is not available
.Exepción: RuntimeError: pycurl transport is not available
Traceback: Traceback (most recent call last):
  File "utils.pyc", line 226, in Conectar
  File "pysimplesoap\transport.pyc", line 257, in set_http_wrapper
  File "pysimplesoap\transport.pyc", line 228, in get_http_wrapper
RuntimeError: pycurl transport is not available

18-10-2018 , Version 2.11a InstallDir C:\PyAfipWs1.18a C:\PyAfipWsappserver status OKdbserver status OKauthserver status OKWSFE.CompUltimoAutorizado(1,1)11002: El punto de venta no se encuentra habilitado a usar en el presente WS. Ver metodo FEParamGetPtosVenta
18-10-2018 , Version 2.11a InstallDir C:\PyAfipWs1.18a C:\PyAfipWsappserver status OKdbserver status OKauthserver status OKWSFE.CompUltimoAutorizado(1,1)11002: El punto de venta no se encuentra habilitado a usar en el presente WS. Ver metodo FEParamGetPtosVenta
18-10-2018 , Version 2.11a InstallDir C:\PyAfipWs1.18a C:\PyAfipWsappserver status OKdbserver status OKauthserver status OKWSFE.CompUltimoAutorizado(1,1)11002: El punto de venta no se encuentra habilitado a usar en el presente WS. Ver metodo FEParamGetPtosVenta
18-10-2018 , Version 2.11a InstallDir C:\PyAfipWs1.18a C:\PyAfipWsappserver status OKdbserver status OKauthserver status OKWSFE.CompUltimoAutorizado(1,1)11002: El punto de venta no se encuentra habilitado a usar en el presente WS. Ver metodo FEParamGetPtosVenta
18-10-2018 , Version 2.11a InstallDir C:\PyAfipWs1.18a C:\PyAfipWsappserver status OKdbserver status OKauthserver status OKWSFE.CompUltimoAutorizado(1,4)11002: El punto de venta no se encuentra habilitado a usar en el presente WS. Ver metodo FEParamGetPtosVenta
18-10-2018 , Version 2.11a InstallDir C:\PyAfipWs1.18a C:\PyAfipWsCodigo error afip:*****Numero de Error: 1429Linea de codigo de error: ok = WSFE.Conectar("",url_wsdl,"",wrapper)      && HomologaciÃ³nProcedimiento: sw_conectarError VFP: Código de excepción OLE IDispatch 0 de Python COM Server Internal Error: Unexpected Python Error: Traceback (most recent call last):
  File "win32com\server\policy.pyc", line 277, in _Invoke_
  File "win32com\server\policy.pyc", line 282, in _invoke_
  File "win32com\server\policy.pyc", line 585, in _invokeex_
  File "utils.pyc", line 226, in Conectar
  File "pysimplesoap\transport.pyc", line 257, in set_http_wrapper
  File "pysimplesoap\transport.pyc", line 228, in get_http_wrapper
RuntimeError: pycurl transport is not available
.Exepción: RuntimeError: pycurl transport is not available
Traceback: Traceback (most recent call last):
  File "utils.pyc", line 226, in Conectar
  File "pysimplesoap\transport.pyc", line 257, in set_http_wrapper
  File "pysimplesoap\transport.pyc", line 228, in get_http_wrapper
RuntimeError: pycurl transport is not available

18-10-2018 , Version 2.11a InstallDir C:\PyAfipWs1.18a C:\PyAfipWsCodigo error afip:*****Numero de Error: 1429Linea de codigo de error: wsfe.SetTicketAcceso(ta)Procedimiento: sw_conectarError VFP: Código de excepción OLE IDispatch 0 de Python COM Server Internal Error: Unexpected Python Error: Traceback (most recent call last):
  File "win32com\server\policy.pyc", line 277, in _Invoke_
  File "win32com\server\policy.pyc", line 282, in _invoke_
  File "win32com\server\policy.pyc", line 585, in _invokeex_
  File "utils.pyc", line 151, in capturar_errores_wrapper
  File "utils.pyc", line 378, in SetTicketAcceso
RuntimeError: Ticket de Acceso vacio!
.Exepción: RuntimeError: Ticket de Acceso vacio!
Traceback: Traceback (most recent call last):
  File "utils.pyc", line 151, in capturar_errores_wrapper
  File "utils.pyc", line 378, in SetTicketAcceso
RuntimeError: Ticket de Acceso vacio!

18-10-2018 , Version 2.11a InstallDir C:\PyAfipWs1.18a C:\PyAfipWsCodigo error afip:*****Numero de Error: 1429Linea de codigo de error: wsfe.SetTicketAcceso(ta)Procedimiento: sw_conectarError VFP: Código de excepción OLE IDispatch 0 de Python COM Server Internal Error: Unexpected Python Error: Traceback (most recent call last):
  File "win32com\server\policy.pyc", line 277, in _Invoke_
  File "win32com\server\policy.pyc", line 282, in _invoke_
  File "win32com\server\policy.pyc", line 585, in _invokeex_
  File "utils.pyc", line 151, in capturar_errores_wrapper
  File "utils.pyc", line 378, in SetTicketAcceso
RuntimeError: Ticket de Acceso vacio!
.Exepción: RuntimeError: Ticket de Acceso vacio!
Traceback: Traceback (most recent call last):
  File "utils.pyc", line 151, in capturar_errores_wrapper
  File "utils.pyc", line 378, in SetTicketAcceso
RuntimeError: Ticket de Acceso vacio!

18-10-2018 , Version 2.11a InstallDir C:\PyAfipWs1.18a C:\PyAfipWsCodigo error afip:*****Numero de Error: 1429Linea de codigo de error: wsfe.SetTicketAcceso(ta)Procedimiento: sw_conectarError VFP: Código de excepción OLE IDispatch 0 de Python COM Server Internal Error: Unexpected Python Error: Traceback (most recent call last):
  File "win32com\server\policy.pyc", line 277, in _Invoke_
  File "win32com\server\policy.pyc", line 282, in _invoke_
  File "win32com\server\policy.pyc", line 585, in _invokeex_
  File "utils.pyc", line 151, in capturar_errores_wrapper
  File "utils.pyc", line 378, in SetTicketAcceso
RuntimeError: Ticket de Acceso vacio!
.Exepción: RuntimeError: Ticket de Acceso vacio!
Traceback: Traceback (most recent call last):
  File "utils.pyc", line 151, in capturar_errores_wrapper
  File "utils.pyc", line 378, in SetTicketAcceso
RuntimeError: Ticket de Acceso vacio!

18-10-2018 , Version 2.11a InstallDir C:\PyAfipWs1.18a C:\PyAfipWsappserver status OKdbserver status OKauthserver status OKWSFE.CompUltimoAutorizado(1,4)Consultamos la fecha del ultimo comprobanteWSFE.CompConsultar(1,4,0)Fecha Ulti: 18-10-2018Orden:110070: Si ImpNeto es mayor a 0 el objeto IVA es obligatorio.602: No existen datos en nuestros registros para los parametros ingresados.
18-10-2018 , Version 2.11a InstallDir C:\PyAfipWs1.18a C:\PyAfipWsappserver status OKdbserver status OKauthserver status OKWSFE.CompUltimoAutorizado(6,4)Consultamos la fecha del ultimo comprobanteWSFE.CompConsultar(6,4,0)Fecha Ulti: 18-10-201810202: Campo CbteNro no lo ingreso o supera el tamaño permitido de 8 caracteres numericos.WSFE.CompUltimoAutorizado(6,4)Consultamos la fecha del ultimo comprobanteWSFE.CompConsultar(6,4,0)Fecha Ulti: 18-10-2018Codigo error afip:0Numero de Error: 1Linea de codigo de error: RENAME this.Pathorigen+cName+".CA1" TO this.Pathorigen+cName+".CA0"Procedimiento: cambiarmoduloError VFP: El archivo 'j:\robotcae\pasaje\afip_fe\fb000001.ca1' no existe.Exepción: ns1:coe.alreadyAuthenticated: El CEE ya posee un TA valido para el acceso al WSN solicitadoTraceback: 10202: Campo CbteNro no lo ingreso o supera el tamaño permitido de 8 caracteres numericos.
18-10-2018 , Version 2.11a InstallDir C:\PyAfipWs1.18a C:\PyAfipWsappserver status OKdbserver status OKauthserver status OKWSFE.CompUltimoAutorizado(6,5)Consultamos la fecha del ultimo comprobanteWSFE.CompConsultar(6,5,0)Fecha Ulti: 18-10-201810202: Campo CbteNro no lo ingreso o supera el tamaño permitido de 8 caracteres numericos.WSFE.CompUltimoAutorizado(6,5)Consultamos la fecha del ultimo comprobanteWSFE.CompConsultar(6,5,0)Fecha Ulti: 18-10-2018Codigo error afip:0Numero de Error: 1Linea de codigo de error: RENAME this.Pathorigen+cName+".CA1" TO this.Pathorigen+cName+".CA0"Procedimiento: cambiarmoduloError VFP: El archivo 'j:\robotcae\pasaje\afip_fe\fb000001.ca1' no existe.Exepción: ns1:coe.alreadyAuthenticated: El CEE ya posee un TA valido para el acceso al WSN solicitadoTraceback: 10202: Campo CbteNro no lo ingreso o supera el tamaño permitido de 8 caracteres numericos.
18-10-2018 , Version 2.11a InstallDir C:\PyAfipWs1.18a C:\PyAfipWsappserver status OKdbserver status OKauthserver status OKWSFE.CompUltimoAutorizado(6,5)Consultamos la fecha del ultimo comprobanteWSFE.CompConsultar(6,5,0)Fecha Ulti: 18-10-2018Orden:110070: Si ImpNeto es mayor a 0 el objeto IVA es obligatorio.602: No existen datos en nuestros registros para los parametros ingresados.
14-11-2018 , Version 2.11a InstallDir C:\PyAfipWs1.18a C:\PyAfipWsCodigo error afip:*****Numero de Error: 1429Linea de codigo de error: wsfe.SetTicketAcceso(ta)Procedimiento: sw_conectarError VFP: Código de excepción OLE IDispatch 0 de Python COM Server Internal Error: Unexpected Python Error: Traceback (most recent call last):
  File "win32com\server\policy.pyc", line 277, in _Invoke_
  File "win32com\server\policy.pyc", line 282, in _invoke_
  File "win32com\server\policy.pyc", line 585, in _invokeex_
  File "utils.pyc", line 151, in capturar_errores_wrapper
  File "utils.pyc", line 378, in SetTicketAcceso
RuntimeError: Ticket de Acceso vacio!
.Exepción: RuntimeError: Ticket de Acceso vacio!
Traceback: Traceback (most recent call last):
  File "utils.pyc", line 151, in capturar_errores_wrapper
  File "utils.pyc", line 378, in SetTicketAcceso
RuntimeError: Ticket de Acceso vacio!

14-11-2018 , Version 2.11a InstallDir C:\PyAfipWs1.18a C:\PyAfipWsappserver status OKdbserver status OKauthserver status OKWSFE.CompUltimoAutorizado(1,5)Consultamos la fecha del ultimo comprobanteWSFE.CompConsultar(1,5,2)Fecha Ulti: 09-11-2018WSFE.CompUltimoAutorizado(1,5)Consultamos la fecha del ultimo comprobanteWSFE.CompConsultar(1,5,2)Fecha Ulti: 09-11-2018Codigo error afip:0Numero de Error: 1Linea de codigo de error: RENAME this.Pathorigen+cName+".CA1" TO this.Pathorigen+cName+".CA0"Procedimiento: cambiarmoduloError VFP: El archivo 'j:\robotcae\pasaje\comprb\fa000002.ca1' no existe.Exepción: ns1:coe.alreadyAuthenticated: El CEE ya posee un TA valido para el acceso al WSN solicitadoTraceback: 
14-11-2018 , Version 2.11a InstallDir C:\PyAfipWs1.18a C:\PyAfipWsappserver status OKdbserver status OKauthserver status OK
14-11-2018 , Version 2.11a InstallDir C:\PyAfipWs1.18a C:\PyAfipWsappserver status OKdbserver status OKauthserver status OK
14-11-2018 , Version 2.11a InstallDir C:\PyAfipWs1.18a C:\PyAfipWsappserver status OKdbserver status OKauthserver status OK
14-11-2018 , Version 2.11a InstallDir C:\PyAfipWs1.18a C:\PyAfipWsappserver status OKdbserver status OKauthserver status OKWSFE.CompUltimoAutorizado(1,5)Consultamos la fecha del ultimo comprobanteWSFE.CompConsultar(1,5,4)Fecha Ulti: 14-11-2018WSFE.CompUltimoAutorizado(1,5)Consultamos la fecha del ultimo comprobanteWSFE.CompConsultar(1,5,4)Fecha Ulti: 14-11-2018Orden:410015: El campo  DocNro es invalido.602: No existen datos en nuestros registros para los parametros ingresados.
21-11-2018 , Version 2.11a InstallDir C:\PyAfipWs1.18a C:\PyAfipWsappserver status OKdbserver status OKauthserver status OKWSFE.CompUltimoAutorizado(1,5)Consultamos la fecha del ultimo comprobanteWSFE.CompConsultar(1,5,10)Fecha Ulti: 14-11-2018WSFE.CompUltimoAutorizado(1,5)Consultamos la fecha del ultimo comprobanteWSFE.CompConsultar(1,5,10)Fecha Ulti: 14-11-2018Orden:110051: Los importes informados en AlicIVA no se corresponden con los porcentajes.602: No existen datos en nuestros registros para los parametros ingresados.
21-11-2018 , Version 2.11a InstallDir C:\PyAfipWs1.18a C:\PyAfipWsappserver status OKdbserver status OKauthserver status OK
21-11-2018 , Version 2.11a InstallDir C:\PyAfipWs1.18a C:\PyAfipWsappserver status OKdbserver status OKauthserver status OK
21-11-2018 , Version 2.11a InstallDir C:\PyAfipWs1.18a C:\PyAfipWsappserver status OKdbserver status OKauthserver status OK
21-11-2018 , Version 2.11a InstallDir C:\PyAfipWs1.18a C:\PyAfipWsappserver status OKdbserver status OKauthserver status OK
21-11-2018 , Version 2.11a InstallDir C:\PyAfipWs1.18a C:\PyAfipWsappserver status OKdbserver status OKauthserver status OK
21-11-2018 , Version 2.11a InstallDir C:\PyAfipWs1.18a C:\PyAfipWsappserver status OKdbserver status OKauthserver status OK
21-11-2018 , Version 2.11a InstallDir C:\PyAfipWs1.18a C:\PyAfipWsappserver status OKdbserver status OKauthserver status OK
21-11-2018 , Version 2.11a InstallDir C:\PyAfipWs1.18a C:\PyAfipWsappserver status OKdbserver status OKauthserver status OK
22-11-2018 , Version 2.11a InstallDir C:\PyAfipWs1.18a C:\PyAfipWsCodigo error afip:*****Numero de Error: 1429Linea de codigo de error: wsfe.SetTicketAcceso(ta)Procedimiento: sw_conectarError VFP: Código de excepción OLE IDispatch 0 de Python COM Server Internal Error: Unexpected Python Error: Traceback (most recent call last):
  File "win32com\server\policy.pyc", line 277, in _Invoke_
  File "win32com\server\policy.pyc", line 282, in _invoke_
  File "win32com\server\policy.pyc", line 585, in _invokeex_
  File "utils.pyc", line 151, in capturar_errores_wrapper
  File "utils.pyc", line 378, in SetTicketAcceso
RuntimeError: Ticket de Acceso vacio!
.Exepción: RuntimeError: Ticket de Acceso vacio!
Traceback: Traceback (most recent call last):
  File "utils.pyc", line 151, in capturar_errores_wrapper
  File "utils.pyc", line 378, in SetTicketAcceso
RuntimeError: Ticket de Acceso vacio!

22-11-2018 , Version 2.11a InstallDir C:\PyAfipWs1.18a C:\PyAfipWsappserver status OKdbserver status OKauthserver status OK
22-11-2018 , Version 2.11a InstallDir C:\PyAfipWs1.18a C:\PyAfipWsappserver status OKdbserver status OKauthserver status OK
22-11-2018 , Iniciando FeedBackTA recuperadoWSSA Version 1.18a WSFE InstallDir C:\PyAfipWsEnviando TAConectando al servicio WSFEConexxion Existosaappserver status OKdbserver status OKauthserver status OK
22-11-2018 , Iniciando FeedBackWSSA Version 2.11a WSSA InstallDir C:\PyAfipWsCertificados ProduccionSolicitando TACodigo error afip:0Numero de Error: 12Linea de codigo de error: IF NOT ISNULL(dFecha)Procedimiento: sw_iniciarError VFP: No se encuentra la variable 'DFECHA'.Exepción: Traceback: 
22-11-2018 , Iniciando FeedBackWSSA Version 2.11a WSSA InstallDir C:\PyAfipWsCertificados ProduccionSolicitando TATA AlmacenadoWSSA Version 1.18a WSFE InstallDir C:\PyAfipWsEnviando TAConectando al servicio WSFEConexxion Existosaappserver status OKdbserver status OKauthserver status OK
22-11-2018 , Iniciando FeedBackCodigo error afip:0Numero de Error: 1429Linea de codigo de error: lsolicitar = WSAA.Expirado(dFecha)Procedimiento: sw_iniciarError VFP: Código de excepción OLE IDispatch 0 de Python COM Server Internal Error: Unexpected Python Error: Traceback (most recent call last):
  File "win32com\server\policy.pyc", line 277, in _Invoke_
  File "win32com\server\policy.pyc", line 282, in _invoke_
  File "win32com\server\policy.pyc", line 585, in _invokeex_
  File "utils.pyc", line 151, in capturar_errores_wrapper
  File "wsaa.pyc", line 277, in Expirado
TypeError: 'time' object has no attribute '__getitem__'
.Exepción: TypeError: 'time' object has no attribute '__getitem__'
Traceback: Traceback (most recent call last):
  File "utils.pyc", line 151, in capturar_errores_wrapper
  File "wsaa.pyc", line 277, in Expirado
TypeError: 'time' object has no attribute '__getitem__'

22-11-2018 , Iniciando FeedBackCodigo error afip:0Numero de Error: 1429Linea de codigo de error: lsolicitar = WSAA.Expirado(dFecha)Procedimiento: sw_iniciarError VFP: Código de excepción OLE IDispatch 0 de Python COM Server Internal Error: Unexpected Python Error: Traceback (most recent call last):
  File "win32com\server\policy.pyc", line 277, in _Invoke_
  File "win32com\server\policy.pyc", line 282, in _invoke_
  File "win32com\server\policy.pyc", line 585, in _invokeex_
  File "utils.pyc", line 151, in capturar_errores_wrapper
  File "wsaa.pyc", line 277, in Expirado
TypeError: 'time' object has no attribute '__getitem__'
.Exepción: TypeError: 'time' object has no attribute '__getitem__'
Traceback: Traceback (most recent call last):
  File "utils.pyc", line 151, in capturar_errores_wrapper
  File "wsaa.pyc", line 277, in Expirado
TypeError: 'time' object has no attribute '__getitem__'

22-11-2018 , Iniciando FeedBackCodigo error afip:0Numero de Error: 11Linea de codigo de error: IF CTOT(This.Tiempoexpiracion) > DATETIME()Procedimiento: sw_iniciarError VFP: El valor, tipo o número de argumentos no es válido para la función.Exepción: ValueError: time data '22-11-2018 11:48:15' does not match format '%Y-%m-%dT%H:%M:%S'
Traceback: Traceback (most recent call last):
  File "utils.pyc", line 151, in capturar_errores_wrapper
  File "wsaa.pyc", line 277, in Expirado
  File "_strptime.pyc", line 325, in _strptime
ValueError: time data '22-11-2018 11:48:15' does not match format '%Y-%m-%dT%H:%M:%S'

22-11-2018 , Iniciando FeedBackWSSA Version 2.11a WSSA InstallDir C:\PyAfipWsCertificados DesarrolloSolicitando TATA AlmacenadoWSSA Version 1.18a WSFE InstallDir C:\PyAfipWsEnviando TAConectando al servicio WSFEConexxion Existosaappserver status OKdbserver status OKauthserver status OK
22-11-2018 , Iniciando FeedBackWSSA Version 2.11a WSSA InstallDir C:\PyAfipWsCertificados DesarrolloSolicitando TAError sw_iniciar pero continuaCódigo de excepción OLE IDispatch 0 de Python COM Server Internal Error: Unexpected Python Error: Traceback (most recent call last):
  File "win32com\server\policy.pyc", line 277, in _Invoke_
  File "win32com\server\policy.pyc", line 282, in _invoke_
  File "win32com\server\policy.pyc", line 585, in _invokeex_
  File "wsaa.pyc", line 266, in CallWSAA
  File "utils.pyc", line 151, in capturar_errores_wrapper
  File "wsaa.pyc", line 255, in LoginCMS
  File "pysimplesoap\client.pyc", line 147, in <lambda>
  File "pysimplesoap\client.pyc", line 342, in wsdl_call
  File "pysimplesoap\client.pyc", line 220, in call
SoapFault: ns1:coe.alreadyAuthenticated: El CEE ya posee un TA valido para el acceso al WSN solicitado
WSSA Version 1.18a WSFE InstallDir C:\PyAfipWsEnviando TAConectando al servicio WSFEConexxion Existosaappserver status OKdbserver status OKauthserver status OK
22-11-2018 , Iniciando FeedBackWSSA Version 2.11a WSSA InstallDir C:\PyAfipWsCertificados ProduccionSolicitando TATA AlmacenadoWSFE Version 1.18a WSFE InstallDir C:\PyAfipWsEnviando TAConectando al servicio WSFEConexxion Existosaappserver status OKdbserver status OKauthserver status OK
22-11-2018 , Iniciando FeedBackWSSA Version 2.11a WSSA InstallDir C:\PyAfipWsCertificados ProduccionSolicitando TATA AlmacenadoWSFE Version 1.18a WSFE InstallDir C:\PyAfipWsEnviando TAConectando al servicio WSFEConexxion Existosaappserver status OKdbserver status OKauthserver status OK
22-11-2018 , Iniciando FeedBackWSSA Version 2.11a WSSA InstallDir C:\PyAfipWsTA recuperadoWSFE Version 1.18a WSFE InstallDir C:\PyAfipWsEnviando TAConectando al servicio WSFEConexxion Existosaappserver status OKdbserver status OKauthserver status OK
