11-09-2015 , Version 2.10d InstallDir C:\PROGRA~1\PyAfipWs1.16d C:\PROGRA~1\PyAfipWsappserver status OKdbserver status OKauthserver status OKWSFE.CompUltimoAutorizado(6,12)Orden:1100003870781419: Para facturas B (CbteDesde igual a CbteHasta) menor a $1000, si DocTipo es distinto a 99, DocNro debe ser mayor a 0.602: No existen datos en nuestros registros para los parametros ingresados.
11-09-2015 , Version 2.10d InstallDir C:\PROGRA~1\PyAfipWs1.16d C:\PROGRA~1\PyAfipWsappserver status OKdbserver status OKauthserver status OKWSFE.CompUltimoAutorizado(6,12)Orden:1100003870781419: Para facturas B (CbteDesde igual a CbteHasta) menor a $1000, si DocTipo es distinto a 99, DocNro debe ser mayor a 0.602: No existen datos en nuestros registros para los parametros ingresados.
11-09-2015 , Version 2.10d InstallDir C:\PROGRA~1\PyAfipWs1.16d C:\PROGRA~1\PyAfipWsappserver status OKdbserver status OKauthserver status OKWSFE.CompUltimoAutorizado(6,12)Orden:1100003870781419: Para facturas B (CbteDesde igual a CbteHasta) menor a $1000, si DocTipo es distinto a 99, DocNro debe ser mayor a 0.602: No existen datos en nuestros registros para los parametros ingresados.
03-12-2015 , Version 2.10b HomologaciónInstallDir C:\PROGRA~1\PyAfipWs1.16d HomologaciónC:\PROGRA~1\PyAfipWsCodigo error afip:*****Numero de Error: 1429Mensaje de Error: Código de excepción OLE IDispatch 0 de Python COM Server Internal Error: Unexpected Python Error: Traceback (most recent call last):
  File "win32com\server\policy.pyc", line 277, in _Invoke_
  File "win32com\server\policy.pyc", line 282, in _invoke_
  File "win32com\server\policy.pyc", line 585, in _invokeex_
  File "utils.pyc", line 152, in capturar_errores_wrapper
  File "utils.pyc", line 375, in SetTicketAcceso
RuntimeError: Ticket de Acceso vacio!
Linea de codigo de error: wsfe.SetTicketAcceso(ta)Procedimiento: sw_conectarError VFP: Código de excepción OLE IDispatch 0 de Python COM Server Internal Error: Unexpected Python Error: Traceback (most recent call last):
  File "win32com\server\policy.pyc", line 277, in _Invoke_
  File "win32com\server\policy.pyc", line 282, in _invoke_
  File "win32com\server\policy.pyc", line 585, in _invokeex_
  File "utils.pyc", line 152, in capturar_errores_wrapper
  File "utils.pyc", line 375, in SetTicketAcceso
RuntimeError: Ticket de Acceso vacio!
.Exepción: RuntimeError: Ticket de Acceso vacio!
Traceback: Traceback (most recent call last):
  File "utils.pyc", line 152, in capturar_errores_wrapper
  File "utils.pyc", line 375, in SetTicketAcceso
RuntimeError: Ticket de Acceso vacio!

